Traceback (most recent call last):
  File "C:\Users\yhc6909\AppData\Local\Programs\Python\Python311\Lib\site-packages\jupyter_cache\executors\utils.py", line 58, in single_nb_execution
    executenb(
  File "C:\Users\yhc6909\AppData\Local\Programs\Python\Python311\Lib\site-packages\nbclient\client.py", line 1314, in execute
    return NotebookClient(nb=nb, resources=resources, km=km, **kwargs).execute()
           ^^^^^^^^^^^^^^^^^^^^^^^^^^^^^^^^^^^^^^^^^^^^^^^^^^^^^^^^^^^^^^^^^^^^^
  File "C:\Users\yhc6909\AppData\Local\Programs\Python\Python311\Lib\site-packages\jupyter_core\utils\__init__.py", line 172, in wrapped
    return loop.run_until_complete(inner)
           ^^^^^^^^^^^^^^^^^^^^^^^^^^^^^^
  File "C:\Users\yhc6909\AppData\Local\Programs\Python\Python311\Lib\asyncio\base_events.py", line 653, in run_until_complete
    return future.result()
           ^^^^^^^^^^^^^^^
  File "C:\Users\yhc6909\AppData\Local\Programs\Python\Python311\Lib\site-packages\nbclient\client.py", line 709, in async_execute
    await self.async_execute_cell(
  File "C:\Users\yhc6909\AppData\Local\Programs\Python\Python311\Lib\site-packages\nbclient\client.py", line 1062, in async_execute_cell
    await self._check_raise_for_error(cell, cell_index, exec_reply)
  File "C:\Users\yhc6909\AppData\Local\Programs\Python\Python311\Lib\site-packages\nbclient\client.py", line 918, in _check_raise_for_error
    raise CellExecutionError.from_cell_and_msg(cell, exec_reply_content)
nbclient.exceptions.CellExecutionError: An error occurred while executing the following cell:
------------------
# establishing connection to Keyspace
session = cluster.connect()
------------------


[1;31m---------------------------------------------------------------------------[0m
[1;31mNoHostAvailable[0m                           Traceback (most recent call last)
Cell [1;32mIn[6], line 2[0m
[0;32m      1[0m [38;5;66;03m# establishing connection to Keyspace[39;00m
[1;32m----> 2[0m session [38;5;241m=[39m [43mcluster[49m[38;5;241;43m.[39;49m[43mconnect[49m[43m([49m[43m)[49m

File [1;32m~\AppData\Local\Programs\Python\Python311\Lib\site-packages\cassandra\cluster.py:1740[0m, in [0;36mCluster.connect[1;34m(self, keyspace, wait_for_all_pools)[0m
[0;32m   1735[0m [38;5;28mself[39m[38;5;241m.[39mload_balancing_policy[38;5;241m.[39mpopulate(
[0;32m   1736[0m     weakref[38;5;241m.[39mproxy([38;5;28mself[39m), [38;5;28mself[39m[38;5;241m.[39mmetadata[38;5;241m.[39mall_hosts()
[0;32m   1737[0m )
[0;32m   1739[0m [38;5;28;01mtry[39;00m:
[1;32m-> 1740[0m     [38;5;28;43mself[39;49m[38;5;241;43m.[39;49m[43mcontrol_connection[49m[38;5;241;43m.[39;49m[43mconnect[49m[43m([49m[43m)[49m
[0;32m   1742[0m     [38;5;66;03m# we set all contact points up for connecting, but we won't infer state after this[39;00m
[0;32m   1743[0m     [38;5;28;01mfor[39;00m endpoint [38;5;129;01min[39;00m [38;5;28mself[39m[38;5;241m.[39mendpoints_resolved:

File [1;32m~\AppData\Local\Programs\Python\Python311\Lib\site-packages\cassandra\cluster.py:3543[0m, in [0;36mControlConnection.connect[1;34m(self)[0m
[0;32m   3540[0m     [38;5;28;01mreturn[39;00m
[0;32m   3542[0m [38;5;28mself[39m[38;5;241m.[39m_protocol_version [38;5;241m=[39m [38;5;28mself[39m[38;5;241m.[39m_cluster[38;5;241m.[39mprotocol_version
[1;32m-> 3543[0m [38;5;28mself[39m[38;5;241m.[39m_set_new_connection([38;5;28;43mself[39;49m[38;5;241;43m.[39;49m[43m_reconnect_internal[49m[43m([49m[43m)[49m)
[0;32m   3545[0m [38;5;28mself[39m[38;5;241m.[39m_cluster[38;5;241m.[39mmetadata[38;5;241m.[39mdbaas [38;5;241m=[39m [38;5;28mself[39m[38;5;241m.[39m_connection[38;5;241m.[39m_product_type [38;5;241m==[39m dscloud[38;5;241m.[39mDATASTAX_CLOUD_PRODUCT_TYPE

File [1;32m~\AppData\Local\Programs\Python\Python311\Lib\site-packages\cassandra\cluster.py:3588[0m, in [0;36mControlConnection._reconnect_internal[1;34m(self)[0m
[0;32m   3585[0m     [38;5;28;01mif[39;00m [38;5;28mself[39m[38;5;241m.[39m_is_shutdown:
[0;32m   3586[0m         [38;5;28;01mraise[39;00m DriverException([38;5;124m"[39m[38;5;124m[control connection] Reconnection in progress during shutdown[39m[38;5;124m"[39m)
[1;32m-> 3588[0m [38;5;28;01mraise[39;00m NoHostAvailable([38;5;124m"[39m[38;5;124mUnable to connect to any servers[39m[38;5;124m"[39m, errors)

[1;31mNoHostAvailable[0m: ('Unable to connect to any servers', {'3.12.23.144:9142': AttributeError("'NoneType' object has no attribute 'access_key'")})

