Traceback (most recent call last):
  File "C:\Users\yhc6909\.venv\de300\Lib\site-packages\jupyter_cache\executors\utils.py", line 58, in single_nb_execution
    executenb(
  File "C:\Users\yhc6909\.venv\de300\Lib\site-packages\nbclient\client.py", line 1305, in execute
    return NotebookClient(nb=nb, resources=resources, km=km, **kwargs).execute()
           ^^^^^^^^^^^^^^^^^^^^^^^^^^^^^^^^^^^^^^^^^^^^^^^^^^^^^^^^^^^^^^^^^^^^^
  File "C:\Users\yhc6909\.venv\de300\Lib\site-packages\jupyter_core\utils\__init__.py", line 165, in wrapped
    return loop.run_until_complete(inner)
           ^^^^^^^^^^^^^^^^^^^^^^^^^^^^^^
  File "C:\Users\yhc6909\AppData\Local\Programs\Python\Python311\Lib\asyncio\base_events.py", line 653, in run_until_complete
    return future.result()
           ^^^^^^^^^^^^^^^
  File "C:\Users\yhc6909\.venv\de300\Lib\site-packages\nbclient\client.py", line 705, in async_execute
    await self.async_execute_cell(
  File "C:\Users\yhc6909\.venv\de300\Lib\site-packages\nbclient\client.py", line 1058, in async_execute_cell
    await self._check_raise_for_error(cell, cell_index, exec_reply)
  File "C:\Users\yhc6909\.venv\de300\Lib\site-packages\nbclient\client.py", line 914, in _check_raise_for_error
    raise CellExecutionError.from_cell_and_msg(cell, exec_reply_content)
nbclient.exceptions.CellExecutionError: An error occurred while executing the following cell:
------------------
# example of variables 
try:
    tables = tabula.read_pdf('https://hcup-us.ahrq.gov/db/state/sidc/tools/cdstats/MI_SIDC_2012_SummaryStats_CORE.PDF', pages='1-8')
except Exception as e:
    tables = tabula.read_pdf('ex-hospital-readmission/MI_SIDC_2012_SummaryStats_CORE.pdf', pages='1-8')
df = pd.concat([tables[i] for i in range(len(tables))], ignore_index=True)
------------------


[1;31m---------------------------------------------------------------------------[0m
[1;31mAttributeError[0m                            Traceback (most recent call last)
Cell [1;32mIn[2], line 3[0m
[0;32m      2[0m [38;5;28;01mtry[39;00m:
[1;32m----> 3[0m     tables [38;5;241m=[39m [43mtabula[49m[38;5;241;43m.[39;49m[43mread_pdf[49m([38;5;124m'[39m[38;5;124mhttps://hcup-us.ahrq.gov/db/state/sidc/tools/cdstats/MI_SIDC_2012_SummaryStats_CORE.PDF[39m[38;5;124m'[39m, pages[38;5;241m=[39m[38;5;124m'[39m[38;5;124m1-8[39m[38;5;124m'[39m)
[0;32m      4[0m [38;5;28;01mexcept[39;00m [38;5;167;01mException[39;00m [38;5;28;01mas[39;00m e:

[1;31mAttributeError[0m: module 'tabula' has no attribute 'read_pdf'

During handling of the above exception, another exception occurred:

[1;31mAttributeError[0m                            Traceback (most recent call last)
Cell [1;32mIn[2], line 5[0m
[0;32m      3[0m     tables [38;5;241m=[39m tabula[38;5;241m.[39mread_pdf([38;5;124m'[39m[38;5;124mhttps://hcup-us.ahrq.gov/db/state/sidc/tools/cdstats/MI_SIDC_2012_SummaryStats_CORE.PDF[39m[38;5;124m'[39m, pages[38;5;241m=[39m[38;5;124m'[39m[38;5;124m1-8[39m[38;5;124m'[39m)
[0;32m      4[0m [38;5;28;01mexcept[39;00m [38;5;167;01mException[39;00m [38;5;28;01mas[39;00m e:
[1;32m----> 5[0m     tables [38;5;241m=[39m [43mtabula[49m[38;5;241;43m.[39;49m[43mread_pdf[49m([38;5;124m'[39m[38;5;124mex-hospital-readmission/MI_SIDC_2012_SummaryStats_CORE.pdf[39m[38;5;124m'[39m, pages[38;5;241m=[39m[38;5;124m'[39m[38;5;124m1-8[39m[38;5;124m'[39m)
[0;32m      6[0m df [38;5;241m=[39m pd[38;5;241m.[39mconcat([tables[i] [38;5;28;01mfor[39;00m i [38;5;129;01min[39;00m [38;5;28mrange[39m([38;5;28mlen[39m(tables))], ignore_index[38;5;241m=[39m[38;5;28;01mTrue[39;00m)

[1;31mAttributeError[0m: module 'tabula' has no attribute 'read_pdf'

